Traceback (most recent call last):
  File "/Users/kgoebber/miniconda3/envs/metpy_book/lib/python3.11/site-packages/jupyter_cache/executors/utils.py", line 58, in single_nb_execution
    executenb(
  File "/Users/kgoebber/miniconda3/envs/metpy_book/lib/python3.11/site-packages/nbclient/client.py", line 1305, in execute
    return NotebookClient(nb=nb, resources=resources, km=km, **kwargs).execute()
           ^^^^^^^^^^^^^^^^^^^^^^^^^^^^^^^^^^^^^^^^^^^^^^^^^^^^^^^^^^^^^^^^^^^^^
  File "/Users/kgoebber/miniconda3/envs/metpy_book/lib/python3.11/site-packages/jupyter_core/utils/__init__.py", line 166, in wrapped
    return loop.run_until_complete(inner)
           ^^^^^^^^^^^^^^^^^^^^^^^^^^^^^^
  File "/Users/kgoebber/miniconda3/envs/metpy_book/lib/python3.11/asyncio/base_events.py", line 653, in run_until_complete
    return future.result()
           ^^^^^^^^^^^^^^^
  File "/Users/kgoebber/miniconda3/envs/metpy_book/lib/python3.11/site-packages/nbclient/client.py", line 705, in async_execute
    await self.async_execute_cell(
  File "/Users/kgoebber/miniconda3/envs/metpy_book/lib/python3.11/site-packages/nbclient/client.py", line 1058, in async_execute_cell
    await self._check_raise_for_error(cell, cell_index, exec_reply)
  File "/Users/kgoebber/miniconda3/envs/metpy_book/lib/python3.11/site-packages/nbclient/client.py", line 914, in _check_raise_for_error
    raise CellExecutionError.from_cell_and_msg(cell, exec_reply_content)
nbclient.exceptions.CellExecutionError: An error occurred while executing the following cell:
------------------
from datetime import datetime

from metpy.units import units
import xarray as xr

# Specify our date/time of product desired
date = datetime(2023, 3, 11, 12)

ds = xr.open_dataset('https://rda.ucar.edu/thredds/dodsC/files/g/ds084.1/'
                     f'{date:%Y}/{date:%Y%m%d}/gfs.0p25.{date:%Y%m%d%H}.f000.grib2')

# Subset data to be just over the CONUS
ds = ds.sel(lat=slice(80, 10), lon=slice(360-145, 360-40))
------------------


[0;31m---------------------------------------------------------------------------[0m
[0;31mModuleNotFoundError[0m                       Traceback (most recent call last)
Cell [0;32mIn[1], line 3[0m
[1;32m      1[0m [38;5;28;01mfrom[39;00m [38;5;21;01mdatetime[39;00m [38;5;28;01mimport[39;00m datetime
[0;32m----> 3[0m [38;5;28;01mfrom[39;00m [38;5;21;01mmetpy[39;00m[38;5;21;01m.[39;00m[38;5;21;01munits[39;00m [38;5;28;01mimport[39;00m units
[1;32m      4[0m [38;5;28;01mimport[39;00m [38;5;21;01mxarray[39;00m [38;5;28;01mas[39;00m [38;5;21;01mxr[39;00m
[1;32m      6[0m [38;5;66;03m# Specify our date/time of product desired[39;00m

[0;31mModuleNotFoundError[0m: No module named 'metpy'

